[2018-Jun-27 23:01] 75.118.88.118 GET http /? 200 OK
[2018-Jun-27 23:01] 75.118.88.118 GET http /? 200 OK
[2018-Jun-27 23:01] 70.39.105.3 GET http /? 200 OK
[2018-Jun-27 23:01] 75.118.88.118 GET http /? 200 OK
[2018-Jun-27 23:01] 75.118.88.118 GET http /? 200 OK
[2018-Jun-27 23:01] 70.39.105.3 GET http /? 200 OK
[2018-Jun-27 23:01] 70.39.105.3 GET http /? 200 OK
[2018-Jun-28 13:01] 127.0.0.1 GET http /? 200 OK
[2018-Jun-28 13:01] 127.0.0.1 GET http /static/css/normalize.css? 200 OK
[2018-Jun-28 13:01] 127.0.0.1 GET http /static/css/demo.css? 200 OK
[2018-Jun-28 13:01] 127.0.0.1 GET http /static/css/component.css? 200 OK
Exception on /favicon.ico [GET]
Traceback (most recent call last):
  File "/home/m/anaconda3/lib/python3.6/site-packages/flask/app.py", line 1813, in full_dispatch_request
    rv = self.dispatch_request()
  File "/home/m/anaconda3/lib/python3.6/site-packages/flask/app.py", line 1791, in dispatch_request
    self.raise_routing_exception(req)
  File "/home/m/anaconda3/lib/python3.6/site-packages/flask/app.py", line 1774, in raise_routing_exception
    raise request.routing_exception
  File "/home/m/anaconda3/lib/python3.6/site-packages/flask/ctx.py", line 336, in match_request
    self.url_adapter.match(return_rule=True)
  File "/home/m/anaconda3/lib/python3.6/site-packages/werkzeug/routing.py", line 1581, in match
    raise NotFound()
werkzeug.exceptions.NotFound: 404 Not Found: The requested URL was not found on the server.  If you entered the URL manually please check your spelling and try again.

During handling of the above exception, another exception occurred:

Traceback (most recent call last):
  File "/home/m/anaconda3/lib/python3.6/site-packages/flask/app.py", line 2292, in wsgi_app
    response = self.full_dispatch_request()
  File "/home/m/anaconda3/lib/python3.6/site-packages/flask/app.py", line 1815, in full_dispatch_request
    rv = self.handle_user_exception(e)
  File "/home/m/anaconda3/lib/python3.6/site-packages/flask/app.py", line 1713, in handle_user_exception
    return self.handle_http_exception(e)
  File "/home/m/anaconda3/lib/python3.6/site-packages/flask/app.py", line 1644, in handle_http_exception
    return handler(e)
  File "/home/m/Dropbox/Projects/OperatorAware/GitPath/operatoraware/app/__init__.py", line 40, in exceptions
    tb = traceback.format_exc()
NameError: name 'traceback' is not defined
[2018-Jun-28 13:04] 127.0.0.1 GET http /? 200 OK
[2018-Jun-28 13:04] 127.0.0.1 GET http /? 200 OK
[2018-Jun-28 13:04] 127.0.0.1 GET http /static/css/normalize.css? 304 NOT MODIFIED
[2018-Jun-28 13:04] 127.0.0.1 GET http /static/css/demo.css? 200 OK
[2018-Jun-28 13:04] 127.0.0.1 GET http /static/css/component.css? 304 NOT MODIFIED
[2018-Jun-28 13:05] 127.0.0.1 GET http /? 200 OK
[2018-Jun-28 13:05] 127.0.0.1 GET http /static/css/normalize.css? 304 NOT MODIFIED
[2018-Jun-28 13:05] 127.0.0.1 GET http /static/css/demo.css? 200 OK
[2018-Jun-28 13:05] 127.0.0.1 GET http /static/css/component.css? 304 NOT MODIFIED
[2018-Jun-28 13:05] 127.0.0.1 GET http /? 200 OK
[2018-Jun-28 13:05] 127.0.0.1 GET http /static/css/component.css? 304 NOT MODIFIED
[2018-Jun-28 13:05] 127.0.0.1 GET http /static/css/normalize.css? 304 NOT MODIFIED
[2018-Jun-28 13:05] 127.0.0.1 GET http /static/css/demo.css? 200 OK
[2018-Jun-28 13:07] 127.0.0.1 GET http /? 200 OK
[2018-Jun-28 13:07] 127.0.0.1 GET http /static/css/normalize.css? 304 NOT MODIFIED
[2018-Jun-28 13:07] 127.0.0.1 GET http /static/css/component.css? 304 NOT MODIFIED
[2018-Jun-28 13:07] 127.0.0.1 GET http /static/css/demo.css? 200 OK
[2018-Jun-28 13:07] 127.0.0.1 GET http /? 200 OK
[2018-Jun-28 13:07] 127.0.0.1 GET http /static/css/normalize.css? 304 NOT MODIFIED
[2018-Jun-28 13:07] 127.0.0.1 GET http /static/css/component.css? 304 NOT MODIFIED
[2018-Jun-28 13:07] 127.0.0.1 GET http /static/css/demo.css? 200 OK
[2018-Jun-28 13:07] 127.0.0.1 GET http /? 200 OK
[2018-Jun-28 13:07] 127.0.0.1 GET http /static/css/normalize.css? 304 NOT MODIFIED
[2018-Jun-28 13:07] 127.0.0.1 GET http /static/css/demo.css? 200 OK
[2018-Jun-28 13:07] 127.0.0.1 GET http /static/css/component.css? 304 NOT MODIFIED
[2018-Jun-28 13:08] 127.0.0.1 GET http /? 200 OK
[2018-Jun-28 13:08] 127.0.0.1 GET http /static/css/normalize.css? 304 NOT MODIFIED
[2018-Jun-28 13:08] 127.0.0.1 GET http /static/css/demo.css? 200 OK
[2018-Jun-28 13:08] 127.0.0.1 GET http /static/css/component.css? 304 NOT MODIFIED
[2018-Jun-28 13:08] 127.0.0.1 GET http /? 200 OK
[2018-Jun-28 13:08] 127.0.0.1 GET http /static/css/component.css? 304 NOT MODIFIED
[2018-Jun-28 13:08] 127.0.0.1 GET http /static/css/normalize.css? 304 NOT MODIFIED
[2018-Jun-28 13:08] 127.0.0.1 GET http /static/css/demo.css? 200 OK
[2018-Jun-28 14:00] 127.0.0.1 GET http /? 200 OK
[2018-Jun-28 14:00] 127.0.0.1 GET http /static/css/demo.css? 200 OK
Exception on / [POST]
Traceback (most recent call last):
  File "/home/m/anaconda3/lib/python3.6/site-packages/flask/app.py", line 1813, in full_dispatch_request
    rv = self.dispatch_request()
  File "/home/m/anaconda3/lib/python3.6/site-packages/flask/app.py", line 1799, in dispatch_request
    return self.view_functions[rule.endpoint](**req.view_args)
  File "/home/m/Dropbox/Projects/OperatorAware/GitPath/operatoraware/app/routes.py", line 34, in indexpost
    authenticated = check_passphrase(pswd_from_user, passphrase_file_path='supervisor_passphrases.keys')
  File "/home/m/Dropbox/Projects/OperatorAware/GitPath/operatoraware/operator_aware_lib/check_passphrase.py", line 11, in check_passphrase
    wordlistFile = open(passphrase_file_path, 'r')  # open wordlist, e.g. BIP39
FileNotFoundError: [Errno 2] No such file or directory: 'supervisor_passphrases.keys'

During handling of the above exception, another exception occurred:

Traceback (most recent call last):
  File "/home/m/anaconda3/lib/python3.6/site-packages/flask/app.py", line 2292, in wsgi_app
    response = self.full_dispatch_request()
  File "/home/m/anaconda3/lib/python3.6/site-packages/flask/app.py", line 1815, in full_dispatch_request
    rv = self.handle_user_exception(e)
  File "/home/m/anaconda3/lib/python3.6/site-packages/flask/app.py", line 1719, in handle_user_exception
    return handler(e)
  File "/home/m/Dropbox/Projects/OperatorAware/GitPath/operatoraware/app/__init__.py", line 40, in exceptions
    tb = traceback.format_exc()
NameError: name 'traceback' is not defined
Exception on / [POST]
Traceback (most recent call last):
  File "/home/m/anaconda3/lib/python3.6/site-packages/flask/app.py", line 1813, in full_dispatch_request
    rv = self.dispatch_request()
  File "/home/m/anaconda3/lib/python3.6/site-packages/flask/app.py", line 1799, in dispatch_request
    return self.view_functions[rule.endpoint](**req.view_args)
  File "/home/m/Dropbox/Projects/OperatorAware/GitPath/operatoraware/app/routes.py", line 34, in indexpost
    authenticated = check_passphrase(pswd_from_user, passphrase_file_path='supervisor_passphrases.keys')
  File "/home/m/Dropbox/Projects/OperatorAware/GitPath/operatoraware/operator_aware_lib/check_passphrase.py", line 11, in check_passphrase
    wordlistFile = open(passphrase_file_path, 'r')  # open wordlist, e.g. BIP39
FileNotFoundError: [Errno 2] No such file or directory: 'supervisor_passphrases.keys'

During handling of the above exception, another exception occurred:

Traceback (most recent call last):
  File "/home/m/anaconda3/lib/python3.6/site-packages/flask/app.py", line 2292, in wsgi_app
    response = self.full_dispatch_request()
  File "/home/m/anaconda3/lib/python3.6/site-packages/flask/app.py", line 1815, in full_dispatch_request
    rv = self.handle_user_exception(e)
  File "/home/m/anaconda3/lib/python3.6/site-packages/flask/app.py", line 1719, in handle_user_exception
    return handler(e)
  File "/home/m/Dropbox/Projects/OperatorAware/GitPath/operatoraware/app/__init__.py", line 40, in exceptions
    tb = traceback.format_exc()
NameError: name 'traceback' is not defined
[2018-Jun-28 14:04] 127.0.0.1 GET http /? 200 OK
Exception on / [POST]
Traceback (most recent call last):
  File "/home/m/anaconda3/lib/python3.6/site-packages/flask/app.py", line 1813, in full_dispatch_request
    rv = self.dispatch_request()
  File "/home/m/anaconda3/lib/python3.6/site-packages/flask/app.py", line 1799, in dispatch_request
    return self.view_functions[rule.endpoint](**req.view_args)
  File "/home/m/Dropbox/Projects/OperatorAware/GitPath/operatoraware/app/routes.py", line 34, in indexpost
    authenticated = check_passphrase(pswd_from_user, passphrase_file_path='supervisor_passphrases.keys')
  File "/home/m/Dropbox/Projects/OperatorAware/GitPath/operatoraware/operator_aware_lib/check_passphrase.py", line 11, in check_passphrase
    wordlistFile = open(passphrase_file_path, 'r')  # open wordlist, e.g. BIP39
FileNotFoundError: [Errno 2] No such file or directory: 'supervisor_passphrases.keys'

During handling of the above exception, another exception occurred:

Traceback (most recent call last):
  File "/home/m/anaconda3/lib/python3.6/site-packages/flask/app.py", line 2292, in wsgi_app
    response = self.full_dispatch_request()
  File "/home/m/anaconda3/lib/python3.6/site-packages/flask/app.py", line 1815, in full_dispatch_request
    rv = self.handle_user_exception(e)
  File "/home/m/anaconda3/lib/python3.6/site-packages/flask/app.py", line 1719, in handle_user_exception
    return handler(e)
  File "/home/m/Dropbox/Projects/OperatorAware/GitPath/operatoraware/app/__init__.py", line 40, in exceptions
    tb = traceback.format_exc()
NameError: name 'traceback' is not defined
[2018-Jun-28 14:05] 127.0.0.1 GET http /? 200 OK
